<?xml version="1.0" ?>
<robot name="tankbot" xmlns:xacro="http://www.ros.org/wiki/xacro">

<xacro:include filename="$(find tankbot_description)/urdf/materials.xacro" />
<xacro:include filename="$(find tankbot_description)/urdf/tankbot.trans" />
<xacro:include filename="$(find tankbot_description)/urdf/tankbot.gazebo" />
<link name="base_link">
  <inertial>
    <origin rpy="0 0 0" xyz="0.04802449670948884 -0.2570000000000001 0.03092345572753796"/>
    <mass value="9.663393854812522"/>
    <inertia ixx="0.050312" ixy="-0.0" ixz="-1.3e-05" iyy="0.087124" iyz="-0.0" izz="0.121613"/>
  </inertial>
  <visual>
    <origin rpy="0 0 0" xyz="0 0 0"/>
    <geometry>
      <mesh filename="package://tankbot_description/meshes/base_link.stl" scale="0.001 0.001 0.001"/>
    </geometry>
    <material name="silver"/>
  </visual>
  <collision>
    <origin rpy="0 0 0" xyz="0 0 0"/>
    <geometry>
      <mesh filename="package://tankbot_description/meshes/base_link.stl" scale="0.001 0.001 0.001"/>
    </geometry>
  </collision>
</link>

<link name="rw3_link_1">
  <inertial>
    <origin rpy="0 0 0" xyz="-5.551115123125783e-17 -0.015000000000000069 -4.163336342344337e-17"/>
    <mass value="1.8496126748009902"/>
    <inertia ixx="0.001295" ixy="0.0" ixz="0.0" iyy="0.002312" iyz="0.0" izz="0.001295"/>
  </inertial>
  <visual>
    <origin rpy="0 0 0" xyz="0.055 0.3635 -0.035"/>
    <geometry>
      <mesh filename="package://tankbot_description/meshes/rw3_link_1.stl" scale="0.001 0.001 0.001"/>
    </geometry>
    <material name="silver"/>
  </visual>
  <collision>
    <origin rpy="0 0 0" xyz="0.055 0.3635 -0.035"/>
    <geometry>
      <mesh filename="package://tankbot_description/meshes/rw3_link_1.stl" scale="0.001 0.001 0.001"/>
    </geometry>
  </collision>
</link>

<link name="rw2_link_1">
  <inertial>
    <origin rpy="0 0 0" xyz="-9.020562075079397e-17 -0.015000000000000513 -1.3877787807814457e-17"/>
    <mass value="1.183752111872634"/>
    <inertia ixx="0.000562" ixy="-0.0" ixz="-0.0" iyy="0.000947" iyz="-0.0" izz="0.000562"/>
  </inertial>
  <visual>
    <origin rpy="0 0 0" xyz="-0.0475 0.3635 -0.035"/>
    <geometry>
      <mesh filename="package://tankbot_description/meshes/rw2_link_1.stl" scale="0.001 0.001 0.001"/>
    </geometry>
    <material name="silver"/>
  </visual>
  <collision>
    <origin rpy="0 0 0" xyz="-0.0475 0.3635 -0.035"/>
    <geometry>
      <mesh filename="package://tankbot_description/meshes/rw2_link_1.stl" scale="0.001 0.001 0.001"/>
    </geometry>
  </collision>
</link>

<link name="rw1_link_1">
  <inertial>
    <origin rpy="0 0 0" xyz="-1.1102230246251565e-16 -0.015000000000000013 2.0816681711721685e-17"/>
    <mass value="1.8496126748009902"/>
    <inertia ixx="0.001295" ixy="0.0" ixz="0.0" iyy="0.002312" iyz="-0.0" izz="0.001295"/>
  </inertial>
  <visual>
    <origin rpy="0 0 0" xyz="-0.15 0.3635 -0.035"/>
    <geometry>
      <mesh filename="package://tankbot_description/meshes/rw1_link_1.stl" scale="0.001 0.001 0.001"/>
    </geometry>
    <material name="silver"/>
  </visual>
  <collision>
    <origin rpy="0 0 0" xyz="-0.15 0.3635 -0.035"/>
    <geometry>
      <mesh filename="package://tankbot_description/meshes/rw1_link_1.stl" scale="0.001 0.001 0.001"/>
    </geometry>
  </collision>
</link>

<link name="lw1_link_1">
  <inertial>
    <origin rpy="0 0 0" xyz="5.551115123125783e-17 0.014999999999999875 1.3877787807814457e-17"/>
    <mass value="1.8496126748009907"/>
    <inertia ixx="0.001295" ixy="0.0" ixz="-0.0" iyy="0.002312" iyz="0.0" izz="0.001295"/>
  </inertial>
  <visual>
    <origin rpy="0 0 0" xyz="-0.1505 0.1505 -0.035"/>
    <geometry>
      <mesh filename="package://tankbot_description/meshes/lw1_link_1.stl" scale="0.001 0.001 0.001"/>
    </geometry>
    <material name="silver"/>
  </visual>
  <collision>
    <origin rpy="0 0 0" xyz="-0.1505 0.1505 -0.035"/>
    <geometry>
      <mesh filename="package://tankbot_description/meshes/lw1_link_1.stl" scale="0.001 0.001 0.001"/>
    </geometry>
  </collision>
</link>

<link name="lw2_link_1">
  <inertial>
    <origin rpy="0 0 0" xyz="2.0816681711721685e-17 0.014999999999999875 -1.3877787807814457e-17"/>
    <mass value="1.183752111872634"/>
    <inertia ixx="0.000562" ixy="0.0" ixz="-0.0" iyy="0.000947" iyz="0.0" izz="0.000562"/>
  </inertial>
  <visual>
    <origin rpy="0 0 0" xyz="-0.048 0.1505 -0.035"/>
    <geometry>
      <mesh filename="package://tankbot_description/meshes/lw2_link_1.stl" scale="0.001 0.001 0.001"/>
    </geometry>
    <material name="silver"/>
  </visual>
  <collision>
    <origin rpy="0 0 0" xyz="-0.048 0.1505 -0.035"/>
    <geometry>
      <mesh filename="package://tankbot_description/meshes/lw2_link_1.stl" scale="0.001 0.001 0.001"/>
    </geometry>
  </collision>
</link>

<link name="lw3_link_1">
  <inertial>
    <origin rpy="0 0 0" xyz="9.020562075079397e-17 0.014999999999999958 0.0"/>
    <mass value="1.8496126748009907"/>
    <inertia ixx="0.001295" ixy="-0.0" ixz="0.0" iyy="0.002312" iyz="0.0" izz="0.001295"/>
  </inertial>
  <visual>
    <origin rpy="0 0 0" xyz="0.0545 0.1505 -0.035"/>
    <geometry>
      <mesh filename="package://tankbot_description/meshes/lw3_link_1.stl" scale="0.001 0.001 0.001"/>
    </geometry>
    <material name="silver"/>
  </visual>
  <collision>
    <origin rpy="0 0 0" xyz="0.0545 0.1505 -0.035"/>
    <geometry>
      <mesh filename="package://tankbot_description/meshes/lw3_link_1.stl" scale="0.001 0.001 0.001"/>
    </geometry>
  </collision>
</link>

<link name="frame_1">
  <inertial>
    <origin rpy="0 0 0" xyz="1.1856979425378666e-07 -1.1102230246251565e-16 0.1270000000000003"/>
    <mass value="4.173751809755388"/>
    <inertia ixx="0.053156" ixy="0.0" ixz="0.0" iyy="0.059602" iyz="0.0" izz="0.047225"/>
  </inertial>
  <visual>
    <origin rpy="0 0 0" xyz="-0.048432 0.2575 -0.09"/>
    <geometry>
      <mesh filename="package://tankbot_description/meshes/frame_1.stl" scale="0.001 0.001 0.001"/>
    </geometry>
    <material name="silver"/>
  </visual>
  <collision>
    <origin rpy="0 0 0" xyz="-0.048432 0.2575 -0.09"/>
    <geometry>
      <mesh filename="package://tankbot_description/meshes/frame_1.stl" scale="0.001 0.001 0.001"/>
    </geometry>
  </collision>
</link>

<link name="holder_1">
  <inertial>
    <origin rpy="0 0 0" xyz="-0.015898641976588364 -0.0001410013794365672 0.03722253654962837"/>
    <mass value="2.1421450013668144"/>
    <inertia ixx="0.010373" ixy="1.1e-05" ixz="6.3e-05" iyy="0.004839" iyz="-5e-06" izz="0.011427"/>
  </inertial>
  <visual>
    <origin rpy="0 0 0" xyz="-0.048432 0.2575 -0.344"/>
    <geometry>
      <mesh filename="package://tankbot_description/meshes/holder_1.stl" scale="0.001 0.001 0.001"/>
    </geometry>
    <material name="silver"/>
  </visual>
  <collision>
    <origin rpy="0 0 0" xyz="-0.048432 0.2575 -0.344"/>
    <geometry>
      <mesh filename="package://tankbot_description/meshes/holder_1.stl" scale="0.001 0.001 0.001"/>
    </geometry>
  </collision>
</link>

<link name="camera_1">
  <inertial>
    <origin rpy="0 0 0" xyz="0.005000020162195945 1.3403930410049725e-07 1.1102230246251565e-16"/>
    <mass value="0.15204665638341558"/>
    <inertia ixx="0.000106" ixy="-0.0" ixz="-0.0" iyy="7e-06" iyz="0.0" izz="0.000102"/>
  </inertial>
  <visual>
    <origin rpy="0 0 0" xyz="-0.072341 0.260428 -0.367"/>
    <geometry>
      <mesh filename="package://tankbot_description/meshes/camera_1.stl" scale="0.001 0.001 0.001"/>
    </geometry>
    <material name="silver"/>
  </visual>
  <collision>
    <origin rpy="0 0 0" xyz="-0.072341 0.260428 -0.367"/>
    <geometry>
      <mesh filename="package://tankbot_description/meshes/camera_1.stl" scale="0.001 0.001 0.001"/>
    </geometry>
  </collision>
</link>

<link name="lidar_1">
  <inertial>
    <origin rpy="0 0 0" xyz="-4.29900122521365e-07 -2.5480986765025193e-09 0.019135896206633696"/>
    <mass value="1.898390048800237"/>
    <inertia ixx="0.001161" ixy="0.0" ixz="-0.0" iyy="0.001161" iyz="-0.0" izz="0.001848"/>
  </inertial>
  <visual>
    <origin rpy="0 0 0" xyz="-0.048387 0.2575 -0.42"/>
    <geometry>
      <mesh filename="package://tankbot_description/meshes/lidar_1.stl" scale="0.001 0.001 0.001"/>
    </geometry>
    <material name="silver"/>
  </visual>
  <collision>
    <origin rpy="0 0 0" xyz="-0.048387 0.2575 -0.42"/>
    <geometry>
      <mesh filename="package://tankbot_description/meshes/lidar_1.stl" scale="0.001 0.001 0.001"/>
    </geometry>
  </collision>
</link>

<joint name="rw3_joint" type="continuous">
  <origin rpy="0 0 0" xyz="-0.055 -0.3635 0.035"/>
  <parent link="base_link"/>
  <child link="rw3_link_1"/>
  <axis xyz="-0.0 -1.0 0.0"/>
</joint>

<joint name="rw2_joint" type="continuous">
  <origin rpy="0 0 0" xyz="0.0475 -0.3635 0.035"/>
  <parent link="base_link"/>
  <child link="rw2_link_1"/>
  <axis xyz="-0.0 -1.0 0.0"/>
</joint>

<joint name="rw1_joint" type="continuous">
  <origin rpy="0 0 0" xyz="0.15 -0.3635 0.035"/>
  <parent link="base_link"/>
  <child link="rw1_link_1"/>
  <axis xyz="-0.0 -1.0 0.0"/>
</joint>

<joint name="lw1_joint" type="continuous">
  <origin rpy="0 0 0" xyz="0.1505 -0.1505 0.035"/>
  <parent link="base_link"/>
  <child link="lw1_link_1"/>
  <axis xyz="0.0 1.0 0.0"/>
</joint>

<joint name="lw2_joint" type="continuous">
  <origin rpy="0 0 0" xyz="0.048 -0.1505 0.035"/>
  <parent link="base_link"/>
  <child link="lw2_link_1"/>
  <axis xyz="0.0 1.0 0.0"/>
</joint>

<joint name="lw3_joint" type="continuous">
  <origin rpy="0 0 0" xyz="-0.0545 -0.1505 0.035"/>
  <parent link="base_link"/>
  <child link="lw3_link_1"/>
  <axis xyz="0.0 1.0 0.0"/>
</joint>

<joint name="frame_joint" type="fixed">
  <origin rpy="0 0 0" xyz="0.048432 -0.2575 0.09"/>
  <parent link="base_link"/>
  <child link="frame_1"/>
</joint>

<joint name="holder_joint" type="fixed">
  <origin rpy="0 0 0" xyz="0.0 0.0 0.254"/>
  <parent link="frame_1"/>
  <child link="holder_1"/>
</joint>

<joint name="camera_joint" type="fixed">
  <origin rpy="0 0 0" xyz="0.023909 -0.002928 0.023"/>
  <parent link="holder_1"/>
  <child link="camera_1"/>
</joint>

<joint name="lidar_joint" type="fixed">
  <origin rpy="0 0 0" xyz="-4.5e-05 0.0 0.076"/>
  <parent link="holder_1"/>
  <child link="lidar_1"/>
</joint>

</robot>
