<?xml version="1.0" ?>
<robot name="tankbot" xmlns:xacro="http://www.ros.org/wiki/xacro">

<xacro:include filename="$(find tankbot_description)/urdf/materials.xacro" />
<xacro:include filename="$(find tankbot_description)/urdf/tankbot.trans" />
<xacro:include filename="$(find tankbot_description)/urdf/tankbot.gazebo" />
<link name="base_link">
  <inertial>
    <origin xyz="-0.0019755032905111897 -0.007000000000000141 0.030923455727537946" rpy="0 0 0"/>
    <mass value="9.66339385481253"/>
    <inertia ixx="0.050312" iyy="0.087124" izz="0.121613" ixy="-0.0" iyz="0.0" ixz="-1.3e-05"/>
  </inertial>
  <visual>
    <origin xyz="0 0 0" rpy="0 0 0"/>
    <geometry>
      <mesh filename="package://tankbot_description/meshes/base_link.stl" scale="0.001 0.001 0.001"/>
    </geometry>
    <material name="silver"/>
  </visual>
  <collision>
    <origin xyz="0 0 0" rpy="0 0 0"/>
    <geometry>
      <mesh filename="package://tankbot_description/meshes/base_link.stl" scale="0.001 0.001 0.001"/>
    </geometry>
  </collision>
</link>

<link name="rw1_link_1">
  <inertial>
    <origin xyz="-2.914335439641036e-16 -0.015000000000000083 -7.632783294297951e-17" rpy="0 0 0"/>
    <mass value="1.6692754390078937"/>
    <inertia ixx="0.001067" iyy="0.001883" izz="0.001067" ixy="0.0" iyz="0.0" ixz="-0.0"/>
  </inertial>
  <visual>
    <origin xyz="-0.1 0.1135 -0.035" rpy="0 0 0"/>
    <geometry>
      <mesh filename="package://tankbot_description/meshes/rw1_link_1.stl" scale="0.001 0.001 0.001"/>
    </geometry>
    <material name="silver"/>
  </visual>
  <collision>
    <origin xyz="-0.1 0.1135 -0.035" rpy="0 0 0"/>
    <geometry>
      <mesh filename="package://tankbot_description/meshes/rw1_link_1.stl" scale="0.001 0.001 0.001"/>
    </geometry>
  </collision>
</link>

<link name="rw2_link_1">
  <inertial>
    <origin xyz="1.5612511283791264e-17 -0.01500000000000025 1.1102230246251565e-16" rpy="0 0 0"/>
    <mass value="1.6692754390078943"/>
    <inertia ixx="0.001067" iyy="0.001883" izz="0.001067" ixy="0.0" iyz="-0.0" ixz="-0.0"/>
  </inertial>
  <visual>
    <origin xyz="0.0025 0.1135 -0.035" rpy="0 0 0"/>
    <geometry>
      <mesh filename="package://tankbot_description/meshes/rw2_link_1.stl" scale="0.001 0.001 0.001"/>
    </geometry>
    <material name="silver"/>
  </visual>
  <collision>
    <origin xyz="0.0025 0.1135 -0.035" rpy="0 0 0"/>
    <geometry>
      <mesh filename="package://tankbot_description/meshes/rw2_link_1.stl" scale="0.001 0.001 0.001"/>
    </geometry>
  </collision>
</link>

<link name="rw3_link_1">
  <inertial>
    <origin xyz="-6.938893903907228e-17 -0.01500000000000011 -4.163336342344337e-17" rpy="0 0 0"/>
    <mass value="1.6692754390078937"/>
    <inertia ixx="0.001067" iyy="0.001883" izz="0.001067" ixy="-0.0" iyz="0.0" ixz="0.0"/>
  </inertial>
  <visual>
    <origin xyz="0.105 0.1135 -0.035" rpy="0 0 0"/>
    <geometry>
      <mesh filename="package://tankbot_description/meshes/rw3_link_1.stl" scale="0.001 0.001 0.001"/>
    </geometry>
    <material name="silver"/>
  </visual>
  <collision>
    <origin xyz="0.105 0.1135 -0.035" rpy="0 0 0"/>
    <geometry>
      <mesh filename="package://tankbot_description/meshes/rw3_link_1.stl" scale="0.001 0.001 0.001"/>
    </geometry>
  </collision>
</link>

<link name="lw3_link_1">
  <inertial>
    <origin xyz="1.249000902703301e-16 0.014999999999999958 6.938893903907228e-18" rpy="0 0 0"/>
    <mass value="1.6692754390078937"/>
    <inertia ixx="0.001067" iyy="0.001883" izz="0.001067" ixy="-0.0" iyz="0.0" ixz="0.0"/>
  </inertial>
  <visual>
    <origin xyz="0.1045 -0.0995 -0.035" rpy="0 0 0"/>
    <geometry>
      <mesh filename="package://tankbot_description/meshes/lw3_link_1.stl" scale="0.001 0.001 0.001"/>
    </geometry>
    <material name="silver"/>
  </visual>
  <collision>
    <origin xyz="0.1045 -0.0995 -0.035" rpy="0 0 0"/>
    <geometry>
      <mesh filename="package://tankbot_description/meshes/lw3_link_1.stl" scale="0.001 0.001 0.001"/>
    </geometry>
  </collision>
</link>

<link name="lw2_link_1">
  <inertial>
    <origin xyz="4.206704429243757e-17 0.014999999999999986 -2.7755575615628914e-17" rpy="0 0 0"/>
    <mass value="1.6692754390078937"/>
    <inertia ixx="0.001067" iyy="0.001883" izz="0.001067" ixy="-0.0" iyz="-0.0" ixz="0.0"/>
  </inertial>
  <visual>
    <origin xyz="0.002 -0.0995 -0.035" rpy="0 0 0"/>
    <geometry>
      <mesh filename="package://tankbot_description/meshes/lw2_link_1.stl" scale="0.001 0.001 0.001"/>
    </geometry>
    <material name="silver"/>
  </visual>
  <collision>
    <origin xyz="0.002 -0.0995 -0.035" rpy="0 0 0"/>
    <geometry>
      <mesh filename="package://tankbot_description/meshes/lw2_link_1.stl" scale="0.001 0.001 0.001"/>
    </geometry>
  </collision>
</link>

<link name="lw1_link_1">
  <inertial>
    <origin xyz="4.163336342344337e-17 0.014999999999999986 -9.020562075079397e-17" rpy="0 0 0"/>
    <mass value="1.6692754390078937"/>
    <inertia ixx="0.001067" iyy="0.001883" izz="0.001067" ixy="0.0" iyz="0.0" ixz="0.0"/>
  </inertial>
  <visual>
    <origin xyz="-0.1005 -0.0995 -0.035" rpy="0 0 0"/>
    <geometry>
      <mesh filename="package://tankbot_description/meshes/lw1_link_1.stl" scale="0.001 0.001 0.001"/>
    </geometry>
    <material name="silver"/>
  </visual>
  <collision>
    <origin xyz="-0.1005 -0.0995 -0.035" rpy="0 0 0"/>
    <geometry>
      <mesh filename="package://tankbot_description/meshes/lw1_link_1.stl" scale="0.001 0.001 0.001"/>
    </geometry>
  </collision>
</link>

<link name="frame_1">
  <inertial>
    <origin xyz="9.410874857174178e-17 -3.382710778154774e-17 0.12700000000000053" rpy="0 0 0"/>
    <mass value="4.173751809755377"/>
    <inertia ixx="0.053156" iyy="0.059602" izz="0.047225" ixy="-0.0" iyz="0.0" ixz="0.0"/>
  </inertial>
  <visual>
    <origin xyz="0.002 0.007 -0.09" rpy="0 0 0"/>
    <geometry>
      <mesh filename="package://tankbot_description/meshes/frame_1.stl" scale="0.001 0.001 0.001"/>
    </geometry>
    <material name="silver"/>
  </visual>
  <collision>
    <origin xyz="0.002 0.007 -0.09" rpy="0 0 0"/>
    <geometry>
      <mesh filename="package://tankbot_description/meshes/frame_1.stl" scale="0.001 0.001 0.001"/>
    </geometry>
  </collision>
</link>

<link name="holder_1">
  <inertial>
    <origin xyz="-0.015898760546382822 -0.0001410013794365464 0.037222536549628205" rpy="0 0 0"/>
    <mass value="2.1421450013668144"/>
    <inertia ixx="0.010373" iyy="0.004839" izz="0.011427" ixy="1.1e-05" iyz="-5e-06" ixz="6.3e-05"/>
  </inertial>
  <visual>
    <origin xyz="-0.018 0.007 -0.344" rpy="0 0 0"/>
    <geometry>
      <mesh filename="package://tankbot_description/meshes/holder_1.stl" scale="0.001 0.001 0.001"/>
    </geometry>
    <material name="silver"/>
  </visual>
  <collision>
    <origin xyz="-0.018 0.007 -0.344" rpy="0 0 0"/>
    <geometry>
      <mesh filename="package://tankbot_description/meshes/holder_1.stl" scale="0.001 0.001 0.001"/>
    </geometry>
  </collision>
</link>

<link name="camera_1">
  <inertial>
    <origin xyz="0.004999901592401532 1.3403930415253895e-07 5.551115123125783e-17" rpy="0 0 0"/>
    <mass value="0.15204665638341558"/>
    <inertia ixx="0.000106" iyy="7e-06" izz="0.000102" ixy="0.0" iyz="-0.0" ixz="0.0"/>
  </inertial>
  <visual>
    <origin xyz="-0.041909 0.009928 -0.367" rpy="0 0 0"/>
    <geometry>
      <mesh filename="package://tankbot_description/meshes/camera_1.stl" scale="0.001 0.001 0.001"/>
    </geometry>
    <material name="silver"/>
  </visual>
  <collision>
    <origin xyz="-0.041909 0.009928 -0.367" rpy="0 0 0"/>
    <geometry>
      <mesh filename="package://tankbot_description/meshes/camera_1.stl" scale="0.001 0.001 0.001"/>
    </geometry>
  </collision>
</link>

<link name="lidar_1">
  <inertial>
    <origin xyz="4.515300830107427e-07 -2.5480985724191108e-09 0.019135896206633585" rpy="0 0 0"/>
    <mass value="1.8983900488002365"/>
    <inertia ixx="0.001161" iyy="0.001161" izz="0.001848" ixy="0.0" iyz="-0.0" ixz="-0.0"/>
  </inertial>
  <visual>
    <origin xyz="-0.017954 0.007 -0.42" rpy="0 0 0"/>
    <geometry>
      <mesh filename="package://tankbot_description/meshes/lidar_1.stl" scale="0.001 0.001 0.001"/>
    </geometry>
    <material name="silver"/>
  </visual>
  <collision>
    <origin xyz="-0.017954 0.007 -0.42" rpy="0 0 0"/>
    <geometry>
      <mesh filename="package://tankbot_description/meshes/lidar_1.stl" scale="0.001 0.001 0.001"/>
    </geometry>
  </collision>
</link>

<joint name="rw1_joint" type="continuous">
  <origin xyz="0.1 -0.1135 0.035" rpy="0 0 0"/>
  <parent link="base_link"/>
  <child link="rw1_link_1"/>
  <axis xyz="-0.0 1.0 0.0"/>
</joint>

<joint name="rw2_joint" type="continuous">
  <origin xyz="-0.0025 -0.1135 0.035" rpy="0 0 0"/>
  <parent link="base_link"/>
  <child link="rw2_link_1"/>
  <axis xyz="-0.0 1.0 0.0"/>
</joint>

<joint name="rw3_joint" type="continuous">
  <origin xyz="-0.105 -0.1135 0.035" rpy="0 0 0"/>
  <parent link="base_link"/>
  <child link="rw3_link_1"/>
  <axis xyz="-0.0 1.0 0.0"/>
</joint>

<joint name="lw3_joint" type="continuous">
  <origin xyz="-0.1045 0.0995 0.035" rpy="0 0 0"/>
  <parent link="base_link"/>
  <child link="lw3_link_1"/>
  <axis xyz="0.0 1.0 0.0"/>
</joint>

<joint name="lw2_joint" type="continuous">
  <origin xyz="-0.002 0.0995 0.035" rpy="0 0 0"/>
  <parent link="base_link"/>
  <child link="lw2_link_1"/>
  <axis xyz="0.0 1.0 0.0"/>
</joint>

<joint name="lw1_joint" type="continuous">
  <origin xyz="0.1005 0.0995 0.035" rpy="0 0 0"/>
  <parent link="base_link"/>
  <child link="lw1_link_1"/>
  <axis xyz="0.0 1.0 0.0"/>
</joint>

<joint name="frame_joint" type="fixed">
  <origin xyz="-0.002 -0.007 0.09" rpy="0 0 0"/>
  <parent link="base_link"/>
  <child link="frame_1"/>
</joint>

<joint name="holder_joint" type="fixed">
  <origin xyz="0.02 0.0 0.254" rpy="0 0 0"/>
  <parent link="frame_1"/>
  <child link="holder_1"/>
</joint>

<joint name="camera_joint" type="fixed">
  <origin xyz="0.023909 -0.002928 0.023" rpy="0 0 0"/>
  <parent link="holder_1"/>
  <child link="camera_1"/>
</joint>

<joint name="lidar_joint" type="fixed">
  <origin xyz="-4.6e-05 0.0 0.076" rpy="0 0 0"/>
  <parent link="holder_1"/>
  <child link="lidar_1"/>
</joint>

</robot>